Workbook

Sheet Summary
A1: W03 Five-Year TCO Analysis
A4: Decision summary
A5: Platform | B5: Technology TCO | C5: Alternative TCO | D5: Five-year savings | E5: Break-even | F5: Approx. payback
A6: Aido Rover | B6: ='Aido Rover'!B43 -> 346631.92 | C6: ='Aido Rover'!B44 -> 450137.02 | D6: ='Aido Rover'!B45 -> 103505.1 | E6: ='Aido Rover'!B48 -> Year 4 | F6: ='Aido Rover'!B49 -> 37.995144
A7: Sentinel Prime AI | B7: ='Sentinel Prime AI'!B36 -> 509446.89 | C7: ='Sentinel Prime AI'!B37 -> 1236433.5 | D7: ='Sentinel Prime AI'!B38 -> 726986.63 | E7: ='Sentinel Prime AI'!B39 -> Year 1 | F7: ='Sentinel Prime AI'!B40 -> 7.634388
A10: Base-case interpretation
A11: Aido Rover | B11: Uses a shared 20 km/day route. Cost per km is the primary comparison; cost per hour remains a secondary view.
A12: Sentinel Prime AI | B12: Supports one 24/7 monitoring post while retaining 25% human oversight.
A13: Largest driver | B13: Avoided human coverage hours and the local wage level determine whether initial deployment costs can be recovered.
A14: Important limit | B14: Rover and the patrol vehicle use the same route, but sensor coverage and emergency response are still different operating functions.
A17: Series | B17: 1 | C17: 2 | D17: 3 | E17: 4 | F17: 5
A18: Aido Rover | B18: ='Aido Rover'!B32 -> 186980.91 | C18: ='Aido Rover'!C32 -> 235371.26 | D18: ='Aido Rover'!D32 -> 269299.81 | E18: ='Aido Rover'!E32 -> 320637.12 | F18: ='Aido Rover'!F32 -> 346631.92
A19: Human patrol | B19: ='Aido Rover'!B33 -> 85040.051 | C19: ='Aido Rover'!C33 -> 172500.08 | D19: ='Aido Rover'!D33 -> 262452.7 | E19: ='Aido Rover'!E33 -> 354972.67 | F19: ='Aido Rover'!F33 -> 450137.02
A22: Series | B22: 1 | C22: 2 | D22: 3 | E22: 4 | F22: 5
A23: Sentinel Prime AI | B23: ='Sentinel Prime AI'!B27 -> 176776.57 | C23: ='Sentinel Prime AI'!C27 -> 257787.7 | D23: ='Sentinel Prime AI'!D27 -> 341229.15 | E23: ='Sentinel Prime AI'!E27 -> 427173.85 | F23: ='Sentinel Prime AI'!F27 -> 509446.89
A24: Human security | B24: ='Sentinel Prime AI'!B28 -> 232887.91 | C24: ='Sentinel Prime AI'!C28 -> 472762.45 | D24: ='Sentinel Prime AI'!D28 -> 719833.23 | E24: ='Sentinel Prime AI'!E28 -> 974316.13 | F24: ='Sentinel Prime AI'!F28 -> 1236433.5

Sheet Assumptions
A1: W03 Five-Year TCO Analysis — Assumptions
A3: Light gray value cells are editable estimates. Public inputs and required assumptions are separately identified.
A5: Model | B5: Input | C5: Value | D5: Unit | E5: Type | F5: Source ID | G5: Derivation / Note
A6: General | B6: Model horizon | C6: 5 | D6: years | E6: Required assumption | F6: S10 | G6: Five-year comparison
A7: General | B7: Annual cost escalation | C7: 0.03 | D7: %/year | E7: Analyst estimate | F7: S10 | G7: Applied to recurring costs; vehicle depreciation stays fixed
A8: General | B8: Commercial electricity price | C8: 0.1341 | D8: USD/kWh | E8: Public source | F8: S03 | G8: 2025 U.S. commercial average; preliminary
A9: General | B9: Regular gasoline price | C9: 3.097 | D9: USD/gallon | E9: Public source | F9: S04 | G9: 2025 annual U.S. average
A10: General | B10: Robot maintenance rate | C10: 0.05 | D10: % hardware/year | E10: Required assumption | F10: S10 | G10: Required by Week 3 assignment
A11: General | B11: Battery cycle life | C11: 1000 | D11: full cycles | E11: Required assumption | F11: S10 | G11: Required by Week 3 assignment
A12: Labor | B12: Security guard median hourly wage | C12: 18.28 | D12: USD/hour | E12: Public source | F12: S01 | G12: BLS OEWS H_MEDIAN for OCC 33-9032; Low sensitivity case
A13: Labor | B13: Security guard mean hourly wage | C13: 20.42 | D13: USD/hour | E13: Public source | F13: S01 | G13: BLS OEWS H_MEAN for OCC 33-9032; Base case
A14: Labor | B14: Security guard 90th-percentile hourly wage | C14: 28.29 | D14: USD/hour | E14: Public source | F14: S01 | G14: BLS OEWS H_PCT90 for OCC 33-9032; High sensitivity case
A15: Labor | B15: ECEC total compensation | C15: 23.63 | D15: USD/hour | E15: Public source | F15: S02 | G15: Service occupations
A16: Labor | B16: ECEC wages and salaries | C16: 18.15 | D16: USD/hour | E16: Public source | F16: S02 | G16: Service occupations
A17: Labor | B17: Benefit load factor | C17: =C15/C16 -> 1.3019284 | D17: x wage | E17: Formula | F17: S02 | G17: Total compensation divided by wages
A18: Labor | B18: Loaded security-guard cost — Base | C18: =C13*C17 -> 26.585377 | D18: USD/hour | E18: Formula | F18: S01/S02 | G18: Mean OEWS wage multiplied by ECEC benefit factor
A19: Conversion | B19: Kilometers per mile | C19: 1.609344 | D19: km/mile | E19: Unit conversion | F19: S10 | G19: Used to convert the shared patrol route to vehicle miles
A20: Vehicle | B20: Combined MPG | C20: 21 | D20: miles/gallon | E20: Derived from source | F20: S05 | G20: Representative midpoint for 2026 Ford Explorer AWD/Tremor AWD
A21: Vehicle | B21: Annual patrol route | C21: =C48 -> 7300 | D21: km/year | E21: Formula | F21: S10 | G21: Same site-required route used for Rover and human patrol
A22: Vehicle | B22: Annual patrol miles | C22: =C21/C19 -> 4536.0097 | D22: miles/year | E22: Formula | F22: S10 | G22: Annual route kilometers divided by kilometers per mile
A23: Vehicle | B23: Full-coverage insurance | C23: 1833 | D23: USD/year | E23: Public source | F23: S06 | G23: AAA Medium SUV (4WD)
A24: Vehicle | B24: Depreciation at 15,000 miles | C24: 4760 | D24: USD/year | E24: Public source | F24: S06 | G24: AAA Medium SUV (4WD) reference value
A25: Vehicle | B25: Low-mileage depreciation reduction | C25: 386 | D25: USD/year | E25: Public source | F25: S06 | G25: AAA 10,000-mile adjustment used as a proxy for the shorter route
A26: Vehicle | B26: Applied annual depreciation | C26: =C24-C25 -> 4374 | D26: USD/year | E26: Formula | F26: S06 | G26: 15,000-mile depreciation less the AAA low-mileage adjustment; held fixed across five years
A27: Vehicle | B27: Maintenance | C27: 0.1179 | D27: USD/mile | E27: Public source | F27: S06 | G27: AAA Medium SUV (4WD)
A28: Vehicle | B28: License / registration / taxes excluded | C28: 835 | D28: USD/year | E28: Excluded item | F28: S06 | G28: Intentionally excluded, which makes the comparison more conservative for Rover
A29: Vehicle | B29: Finance charges excluded | C29: 1190 | D29: USD/year | E29: Excluded item | F29: S06 | G29: Intentionally excluded, which makes the comparison more conservative for Rover
A32: Aido Rover inputs
A33: Model | B33: Input | C33: Value | D33: Unit | E33: Type | F33: Source ID | G33: Derivation / Note
A34: Aido Rover | B34: Hardware cost | C34: 100000 | D34: USD | E34: Public analogue | F34: S07 | G34: Unitree B2 displayed price; not an InGen quote
A35: Aido Rover | B35: Shipping | C35: 0.05 | D35: % hardware | E35: Analyst estimate | F35: S10 | G35: Visible estimate
A36: Aido Rover | B36: Payloads / sensors | C36: 0.2 | D36: % hardware | E36: Analyst estimate | F36: S10 | G36: Thermal/visual inspection payload allowance
A37: Aido Rover | B37: Site preparation | C37: 0.1 | D37: % hardware | E37: Analyst estimate | F37: S10 | G37: Dock and route preparation
A38: Aido Rover | B38: Integration | C38: 0.15 | D38: % hardware | E38: Analyst estimate | F38: S10 | G38: Workflow and system integration
A39: Aido Rover | B39: Training | C39: 0.05 | D39: % hardware | E39: Analyst estimate | F39: S10 | G39: Operator and safety training
A40: Aido Rover | B40: Software / support | C40: 12000 | D40: USD/year | E40: Analyst estimate | F40: S10 | G40: $1,000 per month
A41: Aido Rover | B41: Connectivity | C41: 1200 | D41: USD/year | E41: Analyst estimate | F41: S10 | G41: $100 per month for data service and remote access
A42: Aido Rover | B42: Battery capacity | C42: 2.25 | D42: kWh | E42: Public source | F42: S08 | G42: Unitree B2 battery capacity
A43: Aido Rover | B43: Full equivalent cycles per operating day | C43: 1.6 | D43: cycles/day | E43: Derived estimate | F43: S08/S10 | G43: Eight-hour task divided by a representative five-hour runtime
A44: Aido Rover | B44: Charging efficiency | C44: 0.9 | D44: % | E44: Analyst estimate | F44: S10 | G44: Electricity drawn from the grid after charging losses
...

Sheet Aido Rover
A1: Aido Rover vs. Human Patrol Car — Five-Year TCO
A4: Cost item | B4: 1 | C4: 2 | D4: 3 | E4: 4 | F4: 5
A5: Aido Rover
A6: Hardware | B6: =IF(B$4=1,Assumptions!$C$34,0) -> 100000 | C6: =IF(C$4=1,Assumptions!$C$34,0) -> 0 | D6: =IF(D$4=1,Assumptions!$C$34,0) -> 0 | E6: =IF(E$4=1,Assumptions!$C$34,0) -> 0 | F6: =IF(F$4=1,Assumptions!$C$34,0) -> 0
A7: Shipping | B7: =IF(B$4=1,Assumptions!$C$34*Assumptions!$C$35,0) -> 5000 | C7: =IF(C$4=1,Assumptions!$C$34*Assumptions!$C$35,0) -> 0 | D7: =IF(D$4=1,Assumptions!$C$34*Assumptions!$C$35,0) -> 0 | E7: =IF(E$4=1,Assumptions!$C$34*Assumptions!$C$35,0) -> 0 | F7: =IF(F$4=1,Assumptions!$C$34*Assumptions!$C$35,0) -> 0
A8: Payloads / sensors | B8: =IF(B$4=1,Assumptions!$C$34*Assumptions!$C$36,0) -> 20000 | C8: =IF(C$4=1,Assumptions!$C$34*Assumptions!$C$36,0) -> 0 | D8: =IF(D$4=1,Assumptions!$C$34*Assumptions!$C$36,0) -> 0 | E8: =IF(E$4=1,Assumptions!$C$34*Assumptions!$C$36,0) -> 0 | F8: =IF(F$4=1,Assumptions!$C$34*Assumptions!$C$36,0) -> 0
A9: Site preparation | B9: =IF(B$4=1,Assumptions!$C$34*Assumptions!$C$37,0) -> 10000 | C9: =IF(C$4=1,Assumptions!$C$34*Assumptions!$C$37,0) -> 0 | D9: =IF(D$4=1,Assumptions!$C$34*Assumptions!$C$37,0) -> 0 | E9: =IF(E$4=1,Assumptions!$C$34*Assumptions!$C$37,0) -> 0 | F9: =IF(F$4=1,Assumptions!$C$34*Assumptions!$C$37,0) -> 0
A10: Integration | B10: =IF(B$4=1,Assumptions!$C$34*Assumptions!$C$38,0) -> 15000 | C10: =IF(C$4=1,Assumptions!$C$34*Assumptions!$C$38,0) -> 0 | D10: =IF(D$4=1,Assumptions!$C$34*Assumptions!$C$38,0) -> 0 | E10: =IF(E$4=1,Assumptions!$C$34*Assumptions!$C$38,0) -> 0 | F10: =IF(F$4=1,Assumptions!$C$34*Assumptions!$C$38,0) -> 0
A11: Training | B11: =IF(B$4=1,Assumptions!$C$34*Assumptions!$C$39,0) -> 5000 | C11: =IF(C$4=1,Assumptions!$C$34*Assumptions!$C$39,0) -> 0 | D11: =IF(D$4=1,Assumptions!$C$34*Assumptions!$C$39,0) -> 0 | E11: =IF(E$4=1,Assumptions!$C$34*Assumptions!$C$39,0) -> 0 | F11: =IF(F$4=1,Assumptions!$C$34*Assumptions!$C$39,0) -> 0
A12: Software / support | B12: =Assumptions!$C$40*(1+Assumptions!$C$7)^(B$4-1) -> 12000 | C12: =Assumptions!$C$40*(1+Assumptions!$C$7)^(C$4-1) -> 12360 | D12: =Assumptions!$C$40*(1+Assumptions!$C$7)^(D$4-1) -> 12730.8 | E12: =Assumptions!$C$40*(1+Assumptions!$C$7)^(E$4-1) -> 13112.724 | F12: =Assumptions!$C$40*(1+Assumptions!$C$7)^(F$4-1) -> 13506.106
A13: Connectivity | B13: =Assumptions!$C$41*(1+Assumptions!$C$7)^(B$4-1) -> 1200 | C13: =Assumptions!$C$41*(1+Assumptions!$C$7)^(C$4-1) -> 1236 | D13: =Assumptions!$C$41*(1+Assumptions!$C$7)^(D$4-1) -> 1273.08 | E13: =Assumptions!$C$41*(1+Assumptions!$C$7)^(E$4-1) -> 1311.2724 | F13: =Assumptions!$C$41*(1+Assumptions!$C$7)^(F$4-1) -> 1350.6106
A14: Electricity | B14: =Assumptions!$C$45*Assumptions!$C$46*Assumptions!$C$8*(1+Assumptions!$C$7)^(B$4-1) -> 195.786 | C14: =Assumptions!$C$45*Assumptions!$C$46*Assumptions!$C$8*(1+Assumptions!$C$7)^(C$4-1) -> 201.65958 | D14: =Assumptions!$C$45*Assumptions!$C$46*Assumptions!$C$8*(1+Assumptions!$C$7)^(D$4-1) -> 207.70937 | E14: =Assumptions!$C$45*Assumptions!$C$46*Assumptions!$C$8*(1+Assumptions!$C$7)^(E$4-1) -> 213.94065 | F14: =Assumptions!$C$45*Assumptions!$C$46*Assumptions!$C$8*(1+Assumptions!$C$7)^(F$4-1) -> 220.35887
A15: Maintenance | B15: =Assumptions!$C$34*Assumptions!$C$10*(1+Assumptions!$C$7)^(B$4-1) -> 5000 | C15: =Assumptions!$C$34*Assumptions!$C$10*(1+Assumptions!$C$7)^(C$4-1) -> 5150 | D15: =Assumptions!$C$34*Assumptions!$C$10*(1+Assumptions!$C$7)^(D$4-1) -> 5304.5 | E15: =Assumptions!$C$34*Assumptions!$C$10*(1+Assumptions!$C$7)^(E$4-1) -> 5463.635 | F15: =Assumptions!$C$34*Assumptions!$C$10*(1+Assumptions!$C$7)^(F$4-1) -> 5627.544
A16: Battery replacement | B16: =IF(INT(B$4*Assumptions!$C$46*Assumptions!$C$43/Assumptions!$C$11)>INT((B$4-1)*Assumptions!$C$46*Assumptions!$C$43/Assumptions!$C$11),Assumptions!$C$34*Assumptions!$C$49*(1+Assumptions!$C$7)^(B$4-1),0) -> 0 | C16: =IF(INT(C$4*Assumptions!$C$46*Assumptions!$C$43/Assumptions!$C$11)>INT((C$4-1)*Assumptions!$C$46*Assumptions!$C$43/Assumptions!$C$11),Assumptions!$C$34*Assumptions!$C$49*(1+Assumptions!$C$7)^(C$4-1),0) -> 15450 | D16: =IF(INT(D$4*Assumptions!$C$46*Assumptions!$C$43/Assumptions!$C$11)>INT((D$4-1)*Assumptions!$C$46*Assumptions!$C$43/Assumptions!$C$11),Assumptions!$C$34*Assumptions!$C$49*(1+Assumptions!$C$7)^(D$4-1),0) -> 0 | E16: =IF(INT(E$4*Assumptions!$C$46*Assumptions!$C$43/Assumptions!$C$11)>INT((E$4-1)*Assumptions!$C$46*Assumptions!$C$43/Assumptions!$C$11),Assumptions!$C$34*Assumptions!$C$49*(1+Assumptions!$C$7)^(E$4-1),0) -> 16390.905 | F16: =IF(INT(F$4*Assumptions!$C$46*Assumptions!$C$43/Assumptions!$C$11)>INT((F$4-1)*Assumptions!$C$46*Assumptions!$C$43/Assumptions!$C$11),Assumptions!$C$34*Assumptions!$C$49*(1+Assumptions!$C$7)^(F$4-1),0) -> 0
A17: Human supervision | B17: =Assumptions!$C$50*Assumptions!$C$46*Assumptions!$C$18*(1+Assumptions!$C$7)^(B$4-1) -> 9703.6628 | C17: =Assumptions!$C$50*Assumptions!$C$46*Assumptions!$C$18*(1+Assumptions!$C$7)^(C$4-1) -> 9994.7726 | D17: =Assumptions!$C$50*Assumptions!$C$46*Assumptions!$C$18*(1+Assumptions!$C$7)^(D$4-1) -> 10294.616 | E17: =Assumptions!$C$50*Assumptions!$C$46*Assumptions!$C$18*(1+Assumptions!$C$7)^(E$4-1) -> 10603.454 | F17: =Assumptions!$C$50*Assumptions!$C$46*Assumptions!$C$18*(1+Assumptions!$C$7)^(F$4-1) -> 10921.558
A18: Downtime backup labor | B18: =Assumptions!$C$53*Assumptions!$C$46*Assumptions!$C$51*Assumptions!$C$18*(1+Assumptions!$C$7)^(B$4-1) -> 3881.4651 | C18: =Assumptions!$C$53*Assumptions!$C$46*Assumptions!$C$51*Assumptions!$C$18*(1+Assumptions!$C$7)^(C$4-1) -> 3997.9091 | D18: =Assumptions!$C$53*Assumptions!$C$46*Assumptions!$C$51*Assumptions!$C$18*(1+Assumptions!$C$7)^(D$4-1) -> 4117.8463 | E18: =Assumptions!$C$53*Assumptions!$C$46*Assumptions!$C$51*Assumptions!$C$18*(1+Assumptions!$C$7)^(E$4-1) -> 4241.3817 | F18: =Assumptions!$C$53*Assumptions!$C$46*Assumptions!$C$51*Assumptions!$C$18*(1+Assumptions!$C$7)^(F$4-1) -> 4368.6232
A19: End-of-life value | B19: =IF(B$4=Assumptions!$C$6,-Assumptions!$C$34*Assumptions!$C$52,0) -> 0 | C19: =IF(C$4=Assumptions!$C$6,-Assumptions!$C$34*Assumptions!$C$52,0) -> 0 | D19: =IF(D$4=Assumptions!$C$6,-Assumptions!$C$34*Assumptions!$C$52,0) -> 0 | E19: =IF(E$4=Assumptions!$C$6,-Assumptions!$C$34*Assumptions!$C$52,0) -> 0 | F19: =IF(F$4=Assumptions!$C$6,-Assumptions!$C$34*Assumptions!$C$52,0) -> -10000
A20: Total Aido Rover | B20: =SUM(B6:B19) -> 186980.91 | C20: =SUM(C6:C19) -> 48390.341 | D20: =SUM(D6:D19) -> 33928.552 | E20: =SUM(E6:E19) -> 51337.313 | F20: =SUM(F6:F19) -> 25994.8
A22: Human patrol car
A23: Guard labor and benefits | B23: =Assumptions!$C$53*Assumptions!$C$46*Assumptions!$C$18*(1+Assumptions!$C$7)^(B$4-1) -> 77629.302 | C23: =Assumptions!$C$53*Assumptions!$C$46*Assumptions!$C$18*(1+Assumptions!$C$7)^(C$4-1) -> 79958.181 | D23: =Assumptions!$C$53*Assumptions!$C$46*Assumptions!$C$18*(1+Assumptions!$C$7)^(D$4-1) -> 82356.927 | E23: =Assumptions!$C$53*Assumptions!$C$46*Assumptions!$C$18*(1+Assumptions!$C$7)^(E$4-1) -> 84827.634 | F23: =Assumptions!$C$53*Assumptions!$C$46*Assumptions!$C$18*(1+Assumptions!$C$7)^(F$4-1) -> 87372.463
A24: Fuel | B24: =Assumptions!$C$22/Assumptions!$C$20*Assumptions!$C$9*(1+Assumptions!$C$7)^(B$4-1) -> 668.95343 | C24: =Assumptions!$C$22/Assumptions!$C$20*Assumptions!$C$9*(1+Assumptions!$C$7)^(C$4-1) -> 689.02203 | D24: =Assumptions!$C$22/Assumptions!$C$20*Assumptions!$C$9*(1+Assumptions!$C$7)^(D$4-1) -> 709.69269 | E24: =Assumptions!$C$22/Assumptions!$C$20*Assumptions!$C$9*(1+Assumptions!$C$7)^(E$4-1) -> 730.98348 | F24: =Assumptions!$C$22/Assumptions!$C$20*Assumptions!$C$9*(1+Assumptions!$C$7)^(F$4-1) -> 752.91298
A25: Vehicle maintenance | B25: =Assumptions!$C$22*Assumptions!$C$27*(1+Assumptions!$C$7)^(B$4-1) -> 534.79554 | C25: =Assumptions!$C$22*Assumptions!$C$27*(1+Assumptions!$C$7)^(C$4-1) -> 550.83941 | D25: =Assumptions!$C$22*Assumptions!$C$27*(1+Assumptions!$C$7)^(D$4-1) -> 567.36459 | E25: =Assumptions!$C$22*Assumptions!$C$27*(1+Assumptions!$C$7)^(E$4-1) -> 584.38553 | F25: =Assumptions!$C$22*Assumptions!$C$27*(1+Assumptions!$C$7)^(F$4-1) -> 601.9171
A26: Insurance | B26: =Assumptions!$C$23*(1+Assumptions!$C$7)^(B$4-1) -> 1833 | C26: =Assumptions!$C$23*(1+Assumptions!$C$7)^(C$4-1) -> 1887.99 | D26: =Assumptions!$C$23*(1+Assumptions!$C$7)^(D$4-1) -> 1944.6297 | E26: =Assumptions!$C$23*(1+Assumptions!$C$7)^(E$4-1) -> 2002.9686 | F26: =Assumptions!$C$23*(1+Assumptions!$C$7)^(F$4-1) -> 2063.0576
A27: Depreciation | B27: =Assumptions!$C$26 -> 4374 | C27: =Assumptions!$C$26 -> 4374 | D27: =Assumptions!$C$26 -> 4374 | E27: =Assumptions!$C$26 -> 4374 | F27: =Assumptions!$C$26 -> 4374
A28: Total human patrol | B28: =SUM(B23:B27) -> 85040.051 | C28: =SUM(C23:C27) -> 87460.033 | D28: =SUM(D23:D27) -> 89952.614 | E28: =SUM(E23:E27) -> 92519.972 | F28: =SUM(F23:F27) -> 95164.351
A30: Comparison
A31: Annual savings from Rover | B31: =B28-B20 -> -101940.86 | C31: =C28-C20 -> 39069.691 | D31: =D28-D20 -> 56024.062 | E31: =E28-E20 -> 41182.659 | F31: =F28-F20 -> 69169.551
A32: Cumulative Rover TCO | B32: =SUM($B$20:B20) -> 186980.91 | C32: =SUM($B$20:C20) -> 235371.26 | D32: =SUM($B$20:D20) -> 269299.81 | E32: =SUM($B$20:E20) -> 320637.12 | F32: =SUM($B$20:F20) -> 346631.92
A33: Cumulative human-patrol TCO | B33: =SUM($B$28:B28) -> 85040.051 | C33: =SUM($B$28:C28) -> 172500.08 | D33: =SUM($B$28:D28) -> 262452.7 | E33: =SUM($B$28:E28) -> 354972.67 | F33: =SUM($B$28:F28) -> 450137.02
A34: Cumulative savings | B34: =B33-B32 -> -101940.86 | C34: =C33-C32 -> -62871.172 | D34: =D33-D32 -> -6847.1096 | E34: =E33-E32 -> 34335.549 | F34: =F33-F32 -> 103505.1
A35: Rover cost per patrol km | B35: =B20/Assumptions!$C$48 -> 25.613824 | C35: =C20/Assumptions!$C$48 -> 6.6288139 | D35: =D20/Assumptions!$C$48 -> 4.6477468 | E35: =E20/Assumptions!$C$48 -> 7.0325086 | F35: =F20/Assumptions!$C$48 -> 3.5609315
A36: Human cost per patrol km | B36: =B28/Assumptions!$C$48 -> 11.649322 | C36: =C28/Assumptions!$C$48 -> 11.980826 | D36: =D28/Assumptions!$C$48 -> 12.322276 | E36: =E28/Assumptions!$C$48 -> 12.673969 | F36: =F28/Assumptions!$C$48 -> 13.036212
A37: Rover cost per patrol hour | B37: =B20/(Assumptions!$C$53*Assumptions!$C$46) -> 64.03456 | C37: =C20/(Assumptions!$C$53*Assumptions!$C$46) -> 16.572035 | D37: =D20/(Assumptions!$C$53*Assumptions!$C$46) -> 11.619367 | E37: =E20/(Assumptions!$C$53*Assumptions!$C$46) -> 17.581272 | F37: =F20/(Assumptions!$C$53*Assumptions!$C$46) -> 8.9023289
A38: Human cost per patrol hour | B38: =B28/(Assumptions!$C$53*Assumptions!$C$46) -> 29.123305 | C38: =C28/(Assumptions!$C$53*Assumptions!$C$46) -> 29.952066 | D38: =D28/(Assumptions!$C$53*Assumptions!$C$46) -> 30.80569 | E38: =E28/(Assumptions!$C$53*Assumptions!$C$46) -> 31.684922 | F38: =F28/(Assumptions!$C$53*Assumptions!$C$46) -> 32.590531
A41: Break-even and unit-cost output
A42: Metric | B42: Value | C42: Interpretation
A43: Five-year Aido Rover TCO | B43: =SUM(B20:F20) -> 346631.92 | C43: Includes all listed components and residual value
A44: Five-year human-patrol TCO | B44: =SUM(B28:F28) -> 450137.02 | C44: Loaded labor plus vehicle costs
A45: Five-year savings | B45: =B44-B43 -> 103505.1 | C45: Human patrol TCO minus Rover TCO
A46: Five-year average Rover cost/km | B46: =B43/(Assumptions!C48*Assumptions!C6) -> 9.4967649 | C46: Five-year Rover TCO divided by the shared patrol route
...

Sheet Sentinel Prime AI
A1: Sentinel Prime AI vs. Human Security — Five-Year TCO
A4: Cost item | B4: 1 | C4: 2 | D4: 3 | E4: 4 | F4: 5
A5: Sentinel Prime AI
A6: Hardware / system | B6: =IF(B$4=1,Assumptions!$C$57,0) -> 62500 | C6: =IF(C$4=1,Assumptions!$C$57,0) -> 0 | D6: =IF(D$4=1,Assumptions!$C$57,0) -> 0 | E6: =IF(E$4=1,Assumptions!$C$57,0) -> 0 | F6: =IF(F$4=1,Assumptions!$C$57,0) -> 0
A7: Shipping | B7: =IF(B$4=1,Assumptions!$C$57*Assumptions!$C$58,0) -> 3125 | C7: =IF(C$4=1,Assumptions!$C$57*Assumptions!$C$58,0) -> 0 | D7: =IF(D$4=1,Assumptions!$C$57*Assumptions!$C$58,0) -> 0 | E7: =IF(E$4=1,Assumptions!$C$57*Assumptions!$C$58,0) -> 0 | F7: =IF(F$4=1,Assumptions!$C$57*Assumptions!$C$58,0) -> 0
A8: Additional sensors / payload | B8: =IF(B$4=1,Assumptions!$C$57*Assumptions!$C$59,0) -> 10000 | C8: =IF(C$4=1,Assumptions!$C$57*Assumptions!$C$59,0) -> 0 | D8: =IF(D$4=1,Assumptions!$C$57*Assumptions!$C$59,0) -> 0 | E8: =IF(E$4=1,Assumptions!$C$57*Assumptions!$C$59,0) -> 0 | F8: =IF(F$4=1,Assumptions!$C$57*Assumptions!$C$59,0) -> 0
A9: Site preparation | B9: =IF(B$4=1,Assumptions!$C$57*Assumptions!$C$60,0) -> 5000 | C9: =IF(C$4=1,Assumptions!$C$57*Assumptions!$C$60,0) -> 0 | D9: =IF(D$4=1,Assumptions!$C$57*Assumptions!$C$60,0) -> 0 | E9: =IF(E$4=1,Assumptions!$C$57*Assumptions!$C$60,0) -> 0 | F9: =IF(F$4=1,Assumptions!$C$57*Assumptions!$C$60,0) -> 0
A10: Integration | B10: =IF(B$4=1,Assumptions!$C$57*Assumptions!$C$61,0) -> 12500 | C10: =IF(C$4=1,Assumptions!$C$57*Assumptions!$C$61,0) -> 0 | D10: =IF(D$4=1,Assumptions!$C$57*Assumptions!$C$61,0) -> 0 | E10: =IF(E$4=1,Assumptions!$C$57*Assumptions!$C$61,0) -> 0 | F10: =IF(F$4=1,Assumptions!$C$57*Assumptions!$C$61,0) -> 0
A11: Training | B11: =IF(B$4=1,Assumptions!$C$57*Assumptions!$C$62,0) -> 5000 | C11: =IF(C$4=1,Assumptions!$C$57*Assumptions!$C$62,0) -> 0 | D11: =IF(D$4=1,Assumptions!$C$57*Assumptions!$C$62,0) -> 0 | E11: =IF(E$4=1,Assumptions!$C$57*Assumptions!$C$62,0) -> 0 | F11: =IF(F$4=1,Assumptions!$C$57*Assumptions!$C$62,0) -> 0
A12: Software / monitoring | B12: =Assumptions!$C$63*(1+Assumptions!$C$7)^(B$4-1) -> 12500 | C12: =Assumptions!$C$63*(1+Assumptions!$C$7)^(C$4-1) -> 12875 | D12: =Assumptions!$C$63*(1+Assumptions!$C$7)^(D$4-1) -> 13261.25 | E12: =Assumptions!$C$63*(1+Assumptions!$C$7)^(E$4-1) -> 13659.087 | F12: =Assumptions!$C$63*(1+Assumptions!$C$7)^(F$4-1) -> 14068.86
A13: Electricity | B13: =Assumptions!$C$64*Assumptions!$C$65*Assumptions!$C$8*(1+Assumptions!$C$7)^(B$4-1) -> 146.8395 | C13: =Assumptions!$C$64*Assumptions!$C$65*Assumptions!$C$8*(1+Assumptions!$C$7)^(C$4-1) -> 151.24469 | D13: =Assumptions!$C$64*Assumptions!$C$65*Assumptions!$C$8*(1+Assumptions!$C$7)^(D$4-1) -> 155.78203 | E13: =Assumptions!$C$64*Assumptions!$C$65*Assumptions!$C$8*(1+Assumptions!$C$7)^(E$4-1) -> 160.45549 | F13: =Assumptions!$C$64*Assumptions!$C$65*Assumptions!$C$8*(1+Assumptions!$C$7)^(F$4-1) -> 165.26915
A14: Maintenance | B14: =Assumptions!$C$57*Assumptions!$C$10*(1+Assumptions!$C$7)^(B$4-1) -> 3125 | C14: =Assumptions!$C$57*Assumptions!$C$10*(1+Assumptions!$C$7)^(C$4-1) -> 3218.75 | D14: =Assumptions!$C$57*Assumptions!$C$10*(1+Assumptions!$C$7)^(D$4-1) -> 3315.3125 | E14: =Assumptions!$C$57*Assumptions!$C$10*(1+Assumptions!$C$7)^(E$4-1) -> 3414.7719 | F14: =Assumptions!$C$57*Assumptions!$C$10*(1+Assumptions!$C$7)^(F$4-1) -> 3517.215
A15: Human oversight | B15: =Assumptions!$C$69*Assumptions!$C$65*Assumptions!$C$66*Assumptions!$C$18*(1+Assumptions!$C$7)^(B$4-1) -> 58221.977 | C15: =Assumptions!$C$69*Assumptions!$C$65*Assumptions!$C$66*Assumptions!$C$18*(1+Assumptions!$C$7)^(C$4-1) -> 59968.636 | D15: =Assumptions!$C$69*Assumptions!$C$65*Assumptions!$C$66*Assumptions!$C$18*(1+Assumptions!$C$7)^(D$4-1) -> 61767.695 | E15: =Assumptions!$C$69*Assumptions!$C$65*Assumptions!$C$66*Assumptions!$C$18*(1+Assumptions!$C$7)^(E$4-1) -> 63620.726 | F15: =Assumptions!$C$69*Assumptions!$C$65*Assumptions!$C$66*Assumptions!$C$18*(1+Assumptions!$C$7)^(F$4-1) -> 65529.348
A16: Downtime backup labor | B16: =Assumptions!$C$69*Assumptions!$C$65*Assumptions!$C$67*Assumptions!$C$18*(1+Assumptions!$C$7)^(B$4-1) -> 4657.7581 | C16: =Assumptions!$C$69*Assumptions!$C$65*Assumptions!$C$67*Assumptions!$C$18*(1+Assumptions!$C$7)^(C$4-1) -> 4797.4909 | D16: =Assumptions!$C$69*Assumptions!$C$65*Assumptions!$C$67*Assumptions!$C$18*(1+Assumptions!$C$7)^(D$4-1) -> 4941.4156 | E16: =Assumptions!$C$69*Assumptions!$C$65*Assumptions!$C$67*Assumptions!$C$18*(1+Assumptions!$C$7)^(E$4-1) -> 5089.6581 | F16: =Assumptions!$C$69*Assumptions!$C$65*Assumptions!$C$67*Assumptions!$C$18*(1+Assumptions!$C$7)^(F$4-1) -> 5242.3478
A17: Battery replacement | B17: =Assumptions!$C$70 -> 0 | C17: =Assumptions!$C$70 -> 0 | D17: =Assumptions!$C$70 -> 0 | E17: =Assumptions!$C$70 -> 0 | F17: =Assumptions!$C$70 -> 0
A18: End-of-life value | B18: =IF(B$4=Assumptions!$C$6,-Assumptions!$C$57*Assumptions!$C$68,0) -> 0 | C18: =IF(C$4=Assumptions!$C$6,-Assumptions!$C$57*Assumptions!$C$68,0) -> 0 | D18: =IF(D$4=Assumptions!$C$6,-Assumptions!$C$57*Assumptions!$C$68,0) -> 0 | E18: =IF(E$4=Assumptions!$C$6,-Assumptions!$C$57*Assumptions!$C$68,0) -> 0 | F18: =IF(F$4=Assumptions!$C$6,-Assumptions!$C$57*Assumptions!$C$68,0) -> -6250
A19: Total Sentinel Prime AI | B19: =SUM(B6:B18) -> 176776.57 | C19: =SUM(C6:C18) -> 81011.121 | D19: =SUM(D6:D18) -> 83441.455 | E19: =SUM(E6:E18) -> 85944.699 | F19: =SUM(F6:F18) -> 82273.04
A21: Human security alternative
A22: Guard labor and benefits | B22: =Assumptions!$C$69*Assumptions!$C$65*Assumptions!$C$18*(1+Assumptions!$C$7)^(B$4-1) -> 232887.91 | C22: =Assumptions!$C$69*Assumptions!$C$65*Assumptions!$C$18*(1+Assumptions!$C$7)^(C$4-1) -> 239874.54 | D22: =Assumptions!$C$69*Assumptions!$C$65*Assumptions!$C$18*(1+Assumptions!$C$7)^(D$4-1) -> 247070.78 | E22: =Assumptions!$C$69*Assumptions!$C$65*Assumptions!$C$18*(1+Assumptions!$C$7)^(E$4-1) -> 254482.9 | F22: =Assumptions!$C$69*Assumptions!$C$65*Assumptions!$C$18*(1+Assumptions!$C$7)^(F$4-1) -> 262117.39
A23: Total human security | B23: =B22 -> 232887.91 | C23: =C22 -> 239874.54 | D23: =D22 -> 247070.78 | E23: =E22 -> 254482.9 | F23: =F22 -> 262117.39
A25: Comparison
A26: Annual savings from Sentinel | B26: =B23-B19 -> 56111.332 | C26: =C23-C19 -> 158863.42 | D26: =D23-D19 -> 163629.32 | E26: =E23-E19 -> 168538.2 | F26: =F23-F19 -> 179844.35
A27: Cumulative Sentinel TCO | B27: =SUM($B$19:B19) -> 176776.57 | C27: =SUM($B$19:C19) -> 257787.7 | D27: =SUM($B$19:D19) -> 341229.15 | E27: =SUM($B$19:E19) -> 427173.85 | F27: =SUM($B$19:F19) -> 509446.89
A28: Cumulative human-security TCO | B28: =SUM($B$23:B23) -> 232887.91 | C28: =SUM($B$23:C23) -> 472762.45 | D28: =SUM($B$23:D23) -> 719833.23 | E28: =SUM($B$23:E23) -> 974316.13 | F28: =SUM($B$23:F23) -> 1236433.5
A29: Cumulative savings | B29: =B28-B27 -> 56111.332 | C29: =C28-C27 -> 214974.75 | D29: =D28-D27 -> 378604.08 | E29: =E28-E27 -> 547142.28 | F29: =F28-F27 -> 726986.63
A30: Sentinel cost per monitored hour | B30: =B19/(Assumptions!$C$69*Assumptions!$C$65) -> 20.179974 | C30: =C19/(Assumptions!$C$69*Assumptions!$C$65) -> 9.2478449 | D30: =D19/(Assumptions!$C$69*Assumptions!$C$65) -> 9.5252803 | E30: =E19/(Assumptions!$C$69*Assumptions!$C$65) -> 9.8110387 | F30: =F19/(Assumptions!$C$69*Assumptions!$C$65) -> 9.3918995
A31: Human cost per monitored hour | B31: =B23/(Assumptions!$C$69*Assumptions!$C$65) -> 26.585377 | C31: =C23/(Assumptions!$C$69*Assumptions!$C$65) -> 27.382939 | D31: =D23/(Assumptions!$C$69*Assumptions!$C$65) -> 28.204427 | E31: =E23/(Assumptions!$C$69*Assumptions!$C$65) -> 29.05056 | F31: =F23/(Assumptions!$C$69*Assumptions!$C$65) -> 29.922076
A34: Break-even output
A35: Metric | B35: Value | C35: Interpretation
A36: Five-year Sentinel TCO | B36: =SUM(B19:F19) -> 509446.89 | C36: Includes 25% human oversight and 2% downtime backup
A37: Five-year human-security TCO | B37: =SUM(B23:F23) -> 1236433.5 | C37: Loaded labor for one continuous monitoring post
A38: Five-year savings | B38: =B37-B36 -> 726986.63 | C38: Human-security TCO minus Sentinel TCO
A39: Break-even year | B39: =IF(B29>=0,"Year 1",IF(C29>=0,"Year 2",IF(D29>=0,"Year 3",IF(E29>=0,"Year 4",IF(F29>=0,"Year 5","Beyond 5 years"))))) -> Year 1 | C39: First year with non-negative cumulative savings
A40: Approximate payback | B40: =IF(B23-SUM(B12:B17)<=0,"Beyond 5 years",SUM(B6:B11)/(B23-SUM(B12:B17))*12) -> 7.634388 | C40: Initial deployment cost divided by first-year recurring savings

Sheet Sensitivity
A1: TCO Break-Even Sensitivity
A4: Aido Rover — patrol coverage hours per day
A5: Output | B5: Low | C5: Base | D5: High | E5: Interpretation
A6: Coverage hours/day | B6: 4 | C6: 8 | D6: 12 | E6: Avoided labor hours
A7: Simple payback | B7: =IF(((B6*Assumptions!$C$46*(Assumptions!$C$13*Assumptions!$C$17)+Assumptions!$C$22/Assumptions!$C$20*Assumptions!$C$9+Assumptions!$C$22*Assumptions!$C$27+Assumptions!$C$23+Assumptions!$C$26)-(Assumptions!$C$40+Assumptions!$C$41+Assumptions!$C$45*Assumptions!$C$46*Assumptions!$C$8+Assumptions!$C$34*Assumptions!$C$10+Assumptions!$C$50*Assumptions!$C$46*(Assumptions!$C$13*Assumptions!$C$17)+B6*Assumptions!$C$46*Assumptions!$C$51*(Assumptions!$C$13*Assumptions!$C$17)))<=0,"Beyond 5 years",IF(Assumptions!$C$34*(1+Assumptions!$C$35+Assumptions!$C$36+Assumptions!$C$37+Assumptions!$C$38+Assumptions!$C$39)/((B6*Assumptions!$C$46*(Assumptions!$C$13*Assumptions!$C$17)+Assumptions!$C$22/Assumptions!$C$20*Assumptions!$C$9+Assumptions!$C$22*Assumptions!$C$27+Assumptions!$C$23+Assumptions!$C$26)-(Assumptions!$C$40+Assumptions!$C$41+Assumptions!$C$45*Assumptions!$C$46*Assumptions!$C$8+Assumptions!$C$34*Assumptions!$C$10+Assumptions!$C$50*Assumptions!$C$46*(Assumptions!$C$13*Assumptions!$C$17)+B6*Assumptions!$C$46*Assumptions!$C$51*(Assumptions!$C$13*Assumptions!$C$17)))*12>60,"Beyond 5 years",Assumptions!$C$34*(1+Assumptions!$C$35+Assumptions!$C$36+Assumptions!$C$37+Assumptions!$C$38+Assumptions!$C$39)/((B6*Assumptions!$C$46*(Assumptions!$C$13*Assumptions!$C$17)+Assumptions!$C$22/Assumptions!$C$20*Assumptions!$C$9+Assumptions!$C$22*Assumptions!$C$27+Assumptions!$C$23+Assumptions!$C$26)-(Assumptions!$C$40+Assumptions!$C$41+Assumptions!$C$45*Assumptions!$C$46*Assumptions!$C$8+Assumptions!$C$34*Assumptions!$C$10+Assumptions!$C$50*Assumptions!$C$46*(Assumptions!$C$13*Assumptions!$C$17)+B6*Assumptions!$C$46*Assumptions!$C$51*(Assumptions!$C$13*Assumptions!$C$17)))*12)) -> Beyond 5 years | C7: =IF(((C6*Assumptions!$C$46*(Assumptions!$C$13*Assumptions!$C$17)+Assumptions!$C$22/Assumptions!$C$20*Assumptions!$C$9+Assumptions!$C$22*Assumptions!$C$27+Assumptions!$C$23+Assumptions!$C$26)-(Assumptions!$C$40+Assumptions!$C$41+Assumptions!$C$45*Assumptions!$C$46*Assumptions!$C$8+Assumptions!$C$34*Assumptions!$C$10+Assumptions!$C$50*Assumptions!$C$46*(Assumptions!$C$13*Assumptions!$C$17)+C6*Assumptions!$C$46*Assumptions!$C$51*(Assumptions!$C$13*Assumptions!$C$17)))<=0,"Beyond 5 years",IF(Assumptions!$C$34*(1+Assumptions!$C$35+Assumptions!$C$36+Assumptions!$C$37+Assumptions!$C$38+Assumptions!$C$39)/((C6*Assumptions!$C$46*(Assumptions!$C$13*Assumptions!$C$17)+Assumptions!$C$22/Assumptions!$C$20*Assumptions!$C$9+Assumptions!$C$22*Assumptions!$C$27+Assumptions!$C$23+Assumptions!$C$26)-(Assumptions!$C$40+Assumptions!$C$41+Assumptions!$C$45*Assumptions!$C$46*Assumptions!$C$8+Assumptions!$C$34*Assumptions!$C$10+Assumptions!$C$50*Assumptions!$C$46*(Assumptions!$C$13*Assumptions!$C$17)+C6*Assumptions!$C$46*Assumptions!$C$51*(Assumptions!$C$13*Assumptions!$C$17)))*12>60,"Beyond 5 years",Assumptions!$C$34*(1+Assumptions!$C$35+Assumptions!$C$36+Assumptions!$C$37+Assumptions!$C$38+Assumptions!$C$39)/((C6*Assumptions!$C$46*(Assumptions!$C$13*Assumptions!$C$17)+Assumptions!$C$22/Assumptions!$C$20*Assumptions!$C$9+Assumptions!$C$22*Assumptions!$C$27+Assumptions!$C$23+Assumptions!$C$26)-(Assumptions!$C$40+Assumptions!$C$41+Assumptions!$C$45*Assumptions!$C$46*Assumptions!$C$8+Assumptions!$C$34*Assumptions!$C$10+Assumptions!$C$50*Assumptions!$C$46*(Assumptions!$C$13*Assumptions!$C$17)+C6*Assumptions!$C$46*Assumptions!$C$51*(Assumptions!$C$13*Assumptions!$C$17)))*12)) -> 35.055225 | D7: =IF(((D6*Assumptions!$C$46*(Assumptions!$C$13*Assumptions!$C$17)+Assumptions!$C$22/Assumptions!$C$20*Assumptions!$C$9+Assumptions!$C$22*Assumptions!$C$27+Assumptions!$C$23+Assumptions!$C$26)-(Assumptions!$C$40+Assumptions!$C$41+Assumptions!$C$45*Assumptions!$C$46*Assumptions!$C$8+Assumptions!$C$34*Assumptions!$C$10+Assumptions!$C$50*Assumptions!$C$46*(Assumptions!$C$13*Assumptions!$C$17)+D6*Assumptions!$C$46*Assumptions!$C$51*(Assumptions!$C$13*Assumptions!$C$17)))<=0,"Beyond 5 years",IF(Assumptions!$C$34*(1+Assumptions!$C$35+Assumptions!$C$36+Assumptions!$C$37+Assumptions!$C$38+Assumptions!$C$39)/((D6*Assumptions!$C$46*(Assumptions!$C$13*Assumptions!$C$17)+Assumptions!$C$22/Assumptions!$C$20*Assumptions!$C$9+Assumptions!$C$22*Assumptions!$C$27+Assumptions!$C$23+Assumptions!$C$26)-(Assumptions!$C$40+Assumptions!$C$41+Assumptions!$C$45*Assumptions!$C$46*Assumptions!$C$8+Assumptions!$C$34*Assumptions!$C$10+Assumptions!$C$50*Assumptions!$C$46*(Assumptions!$C$13*Assumptions!$C$17)+D6*Assumptions!$C$46*Assumptions!$C$51*(Assumptions!$C$13*Assumptions!$C$17)))*12>60,"Beyond 5 years",Assumptions!$C$34*(1+Assumptions!$C$35+Assumptions!$C$36+Assumptions!$C$37+Assumptions!$C$38+Assumptions!$C$39)/((D6*Assumptions!$C$46*(Assumptions!$C$13*Assumptions!$C$17)+Assumptions!$C$22/Assumptions!$C$20*Assumptions!$C$9+Assumptions!$C$22*Assumptions!$C$27+Assumptions!$C$23+Assumptions!$C$26)-(Assumptions!$C$40+Assumptions!$C$41+Assumptions!$C$45*Assumptions!$C$46*Assumptions!$C$8+Assumptions!$C$34*Assumptions!$C$10+Assumptions!$C$50*Assumptions!$C$46*(Assumptions!$C$13*Assumptions!$C$17)+D6*Assumptions!$C$46*Assumptions!$C$51*(Assumptions!$C$13*Assumptions!$C$17)))*12)) -> 20.682051 | E7: Initial deployment cost / annual recurring savings
A10: Aido Rover — hardware cost
A11: Output | B11: Low | C11: Base | D11: High | E11: Interpretation
A12: Hardware cost | B12: 80000 | C12: 100000 | D12: 125000 | E12: Public analogue tested around base case
A13: Simple payback | B13: =IF(((Assumptions!$C$53*Assumptions!$C$46*(Assumptions!$C$13*Assumptions!$C$17)+Assumptions!$C$22/Assumptions!$C$20*Assumptions!$C$9+Assumptions!$C$22*Assumptions!$C$27+Assumptions!$C$23+Assumptions!$C$26)-(Assumptions!$C$40+Assumptions!$C$41+Assumptions!$C$45*Assumptions!$C$46*Assumptions!$C$8+B12*Assumptions!$C$10+Assumptions!$C$50*Assumptions!$C$46*(Assumptions!$C$13*Assumptions!$C$17)+Assumptions!$C$53*Assumptions!$C$46*Assumptions!$C$51*(Assumptions!$C$13*Assumptions!$C$17)))<=0,"Beyond 5 years",IF(B12*(1+Assumptions!$C$35+Assumptions!$C$36+Assumptions!$C$37+Assumptions!$C$38+Assumptions!$C$39)/((Assumptions!$C$53*Assumptions!$C$46*(Assumptions!$C$13*Assumptions!$C$17)+Assumptions!$C$22/Assumptions!$C$20*Assumptions!$C$9+Assumptions!$C$22*Assumptions!$C$27+Assumptions!$C$23+Assumptions!$C$26)-(Assumptions!$C$40+Assumptions!$C$41+Assumptions!$C$45*Assumptions!$C$46*Assumptions!$C$8+B12*Assumptions!$C$10+Assumptions!$C$50*Assumptions!$C$46*(Assumptions!$C$13*Assumptions!$C$17)+Assumptions!$C$53*Assumptions!$C$46*Assumptions!$C$51*(Assumptions!$C$13*Assumptions!$C$17)))*12>60,"Beyond 5 years",B12*(1+Assumptions!$C$35+Assumptions!$C$36+Assumptions!$C$37+Assumptions!$C$38+Assumptions!$C$39)/((Assumptions!$C$53*Assumptions!$C$46*(Assumptions!$C$13*Assumptions!$C$17)+Assumptions!$C$22/Assumptions!$C$20*Assumptions!$C$9+Assumptions!$C$22*Assumptions!$C$27+Assumptions!$C$23+Assumptions!$C$26)-(Assumptions!$C$40+Assumptions!$C$41+Assumptions!$C$45*Assumptions!$C$46*Assumptions!$C$8+B12*Assumptions!$C$10+Assumptions!$C$50*Assumptions!$C$46*(Assumptions!$C$13*Assumptions!$C$17)+Assumptions!$C$53*Assumptions!$C$46*Assumptions!$C$51*(Assumptions!$C$13*Assumptions!$C$17)))*12)) -> 27.525412 | C13: =IF(((Assumptions!$C$53*Assumptions!$C$46*(Assumptions!$C$13*Assumptions!$C$17)+Assumptions!$C$22/Assumptions!$C$20*Assumptions!$C$9+Assumptions!$C$22*Assumptions!$C$27+Assumptions!$C$23+Assumptions!$C$26)-(Assumptions!$C$40+Assumptions!$C$41+Assumptions!$C$45*Assumptions!$C$46*Assumptions!$C$8+C12*Assumptions!$C$10+Assumptions!$C$50*Assumptions!$C$46*(Assumptions!$C$13*Assumptions!$C$17)+Assumptions!$C$53*Assumptions!$C$46*Assumptions!$C$51*(Assumptions!$C$13*Assumptions!$C$17)))<=0,"Beyond 5 years",IF(C12*(1+Assumptions!$C$35+Assumptions!$C$36+Assumptions!$C$37+Assumptions!$C$38+Assumptions!$C$39)/((Assumptions!$C$53*Assumptions!$C$46*(Assumptions!$C$13*Assumptions!$C$17)+Assumptions!$C$22/Assumptions!$C$20*Assumptions!$C$9+Assumptions!$C$22*Assumptions!$C$27+Assumptions!$C$23+Assumptions!$C$26)-(Assumptions!$C$40+Assumptions!$C$41+Assumptions!$C$45*Assumptions!$C$46*Assumptions!$C$8+C12*Assumptions!$C$10+Assumptions!$C$50*Assumptions!$C$46*(Assumptions!$C$13*Assumptions!$C$17)+Assumptions!$C$53*Assumptions!$C$46*Assumptions!$C$51*(Assumptions!$C$13*Assumptions!$C$17)))*12>60,"Beyond 5 years",C12*(1+Assumptions!$C$35+Assumptions!$C$36+Assumptions!$C$37+Assumptions!$C$38+Assumptions!$C$39)/((Assumptions!$C$53*Assumptions!$C$46*(Assumptions!$C$13*Assumptions!$C$17)+Assumptions!$C$22/Assumptions!$C$20*Assumptions!$C$9+Assumptions!$C$22*Assumptions!$C$27+Assumptions!$C$23+Assumptions!$C$26)-(Assumptions!$C$40+Assumptions!$C$41+Assumptions!$C$45*Assumptions!$C$46*Assumptions!$C$8+C12*Assumptions!$C$10+Assumptions!$C$50*Assumptions!$C$46*(Assumptions!$C$13*Assumptions!$C$17)+Assumptions!$C$53*Assumptions!$C$46*Assumptions!$C$51*(Assumptions!$C$13*Assumptions!$C$17)))*12)) -> 35.055225 | D13: =IF(((Assumptions!$C$53*Assumptions!$C$46*(Assumptions!$C$13*Assumptions!$C$17)+Assumptions!$C$22/Assumptions!$C$20*Assumptions!$C$9+Assumptions!$C$22*Assumptions!$C$27+Assumptions!$C$23+Assumptions!$C$26)-(Assumptions!$C$40+Assumptions!$C$41+Assumptions!$C$45*Assumptions!$C$46*Assumptions!$C$8+D12*Assumptions!$C$10+Assumptions!$C$50*Assumptions!$C$46*(Assumptions!$C$13*Assumptions!$C$17)+Assumptions!$C$53*Assumptions!$C$46*Assumptions!$C$51*(Assumptions!$C$13*Assumptions!$C$17)))<=0,"Beyond 5 years",IF(D12*(1+Assumptions!$C$35+Assumptions!$C$36+Assumptions!$C$37+Assumptions!$C$38+Assumptions!$C$39)/((Assumptions!$C$53*Assumptions!$C$46*(Assumptions!$C$13*Assumptions!$C$17)+Assumptions!$C$22/Assumptions!$C$20*Assumptions!$C$9+Assumptions!$C$22*Assumptions!$C$27+Assumptions!$C$23+Assumptions!$C$26)-(Assumptions!$C$40+Assumptions!$C$41+Assumptions!$C$45*Assumptions!$C$46*Assumptions!$C$8+D12*Assumptions!$C$10+Assumptions!$C$50*Assumptions!$C$46*(Assumptions!$C$13*Assumptions!$C$17)+Assumptions!$C$53*Assumptions!$C$46*Assumptions!$C$51*(Assumptions!$C$13*Assumptions!$C$17)))*12>60,"Beyond 5 years",D12*(1+Assumptions!$C$35+Assumptions!$C$36+Assumptions!$C$37+Assumptions!$C$38+Assumptions!$C$39)/((Assumptions!$C$53*Assumptions!$C$46*(Assumptions!$C$13*Assumptions!$C$17)+Assumptions!$C$22/Assumptions!$C$20*Assumptions!$C$9+Assumptions!$C$22*Assumptions!$C$27+Assumptions!$C$23+Assumptions!$C$26)-(Assumptions!$C$40+Assumptions!$C$41+Assumptions!$C$45*Assumptions!$C$46*Assumptions!$C$8+D12*Assumptions!$C$10+Assumptions!$C$50*Assumptions!$C$46*(Assumptions!$C$13*Assumptions!$C$17)+Assumptions!$C$53*Assumptions!$C$46*Assumptions!$C$51*(Assumptions!$C$13*Assumptions!$C$17)))*12)) -> 44.876254 | E13: Coverage remains at 8 hours/day
A16: Aido Rover — daily electricity use
A17: Output | B17: Low | C17: Base | D17: High | E17: Interpretation
A18: Daily energy | B18: 3 | C18: 4 | D18: 5 | E18: Charging and duty-cycle range around the 4 kWh/day base
A19: Simple payback | B19: =IF(((Assumptions!$C$53*Assumptions!$C$46*(Assumptions!$C$13*Assumptions!$C$17)+Assumptions!$C$22/Assumptions!$C$20*Assumptions!$C$9+Assumptions!$C$22*Assumptions!$C$27+Assumptions!$C$23+Assumptions!$C$26)-(Assumptions!$C$40+Assumptions!$C$41+B18*Assumptions!$C$46*Assumptions!$C$8+Assumptions!$C$34*Assumptions!$C$10+Assumptions!$C$50*Assumptions!$C$46*(Assumptions!$C$13*Assumptions!$C$17)+Assumptions!$C$53*Assumptions!$C$46*Assumptions!$C$51*(Assumptions!$C$13*Assumptions!$C$17)))<=0,"Beyond 5 years",IF(Assumptions!$C$34*(1+Assumptions!$C$35+Assumptions!$C$36+Assumptions!$C$37+Assumptions!$C$38+Assumptions!$C$39)/((Assumptions!$C$53*Assumptions!$C$46*(Assumptions!$C$13*Assumptions!$C$17)+Assumptions!$C$22/Assumptions!$C$20*Assumptions!$C$9+Assumptions!$C$22*Assumptions!$C$27+Assumptions!$C$23+Assumptions!$C$26)-(Assumptions!$C$40+Assumptions!$C$41+B18*Assumptions!$C$46*Assumptions!$C$8+Assumptions!$C$34*Assumptions!$C$10+Assumptions!$C$50*Assumptions!$C$46*(Assumptions!$C$13*Assumptions!$C$17)+Assumptions!$C$53*Assumptions!$C$46*Assumptions!$C$51*(Assumptions!$C$13*Assumptions!$C$17)))*12>60,"Beyond 5 years",Assumptions!$C$34*(1+Assumptions!$C$35+Assumptions!$C$36+Assumptions!$C$37+Assumptions!$C$38+Assumptions!$C$39)/((Assumptions!$C$53*Assumptions!$C$46*(Assumptions!$C$13*Assumptions!$C$17)+Assumptions!$C$22/Assumptions!$C$20*Assumptions!$C$9+Assumptions!$C$22*Assumptions!$C$27+Assumptions!$C$23+Assumptions!$C$26)-(Assumptions!$C$40+Assumptions!$C$41+B18*Assumptions!$C$46*Assumptions!$C$8+Assumptions!$C$34*Assumptions!$C$10+Assumptions!$C$50*Assumptions!$C$46*(Assumptions!$C$13*Assumptions!$C$17)+Assumptions!$C$53*Assumptions!$C$46*Assumptions!$C$51*(Assumptions!$C$13*Assumptions!$C$17)))*12)) -> 35.022917 | C19: =IF(((Assumptions!$C$53*Assumptions!$C$46*(Assumptions!$C$13*Assumptions!$C$17)+Assumptions!$C$22/Assumptions!$C$20*Assumptions!$C$9+Assumptions!$C$22*Assumptions!$C$27+Assumptions!$C$23+Assumptions!$C$26)-(Assumptions!$C$40+Assumptions!$C$41+C18*Assumptions!$C$46*Assumptions!$C$8+Assumptions!$C$34*Assumptions!$C$10+Assumptions!$C$50*Assumptions!$C$46*(Assumptions!$C$13*Assumptions!$C$17)+Assumptions!$C$53*Assumptions!$C$46*Assumptions!$C$51*(Assumptions!$C$13*Assumptions!$C$17)))<=0,"Beyond 5 years",IF(Assumptions!$C$34*(1+Assumptions!$C$35+Assumptions!$C$36+Assumptions!$C$37+Assumptions!$C$38+Assumptions!$C$39)/((Assumptions!$C$53*Assumptions!$C$46*(Assumptions!$C$13*Assumptions!$C$17)+Assumptions!$C$22/Assumptions!$C$20*Assumptions!$C$9+Assumptions!$C$22*Assumptions!$C$27+Assumptions!$C$23+Assumptions!$C$26)-(Assumptions!$C$40+Assumptions!$C$41+C18*Assumptions!$C$46*Assumptions!$C$8+Assumptions!$C$34*Assumptions!$C$10+Assumptions!$C$50*Assumptions!$C$46*(Assumptions!$C$13*Assumptions!$C$17)+Assumptions!$C$53*Assumptions!$C$46*Assumptions!$C$51*(Assumptions!$C$13*Assumptions!$C$17)))*12>60,"Beyond 5 years",Assumptions!$C$34*(1+Assumptions!$C$35+Assumptions!$C$36+Assumptions!$C$37+Assumptions!$C$38+Assumptions!$C$39)/((Assumptions!$C$53*Assumptions!$C$46*(Assumptions!$C$13*Assumptions!$C$17)+Assumptions!$C$22/Assumptions!$C$20*Assumptions!$C$9+Assumptions!$C$22*Assumptions!$C$27+Assumptions!$C$23+Assumptions!$C$26)-(Assumptions!$C$40+Assumptions!$C$41+C18*Assumptions!$C$46*Assumptions!$C$8+Assumptions!$C$34*Assumptions!$C$10+Assumptions!$C$50*Assumptions!$C$46*(Assumptions!$C$13*Assumptions!$C$17)+Assumptions!$C$53*Assumptions!$C$46*Assumptions!$C$51*(Assumptions!$C$13*Assumptions!$C$17)))*12)) -> 35.055225 | D19: =IF(((Assumptions!$C$53*Assumptions!$C$46*(Assumptions!$C$13*Assumptions!$C$17)+Assumptions!$C$22/Assumptions!$C$20*Assumptions!$C$9+Assumptions!$C$22*Assumptions!$C$27+Assumptions!$C$23+Assumptions!$C$26)-(Assumptions!$C$40+Assumptions!$C$41+D18*Assumptions!$C$46*Assumptions!$C$8+Assumptions!$C$34*Assumptions!$C$10+Assumptions!$C$50*Assumptions!$C$46*(Assumptions!$C$13*Assumptions!$C$17)+Assumptions!$C$53*Assumptions!$C$46*Assumptions!$C$51*(Assumptions!$C$13*Assumptions!$C$17)))<=0,"Beyond 5 years",IF(Assumptions!$C$34*(1+Assumptions!$C$35+Assumptions!$C$36+Assumptions!$C$37+Assumptions!$C$38+Assumptions!$C$39)/((Assumptions!$C$53*Assumptions!$C$46*(Assumptions!$C$13*Assumptions!$C$17)+Assumptions!$C$22/Assumptions!$C$20*Assumptions!$C$9+Assumptions!$C$22*Assumptions!$C$27+Assumptions!$C$23+Assumptions!$C$26)-(Assumptions!$C$40+Assumptions!$C$41+D18*Assumptions!$C$46*Assumptions!$C$8+Assumptions!$C$34*Assumptions!$C$10+Assumptions!$C$50*Assumptions!$C$46*(Assumptions!$C$13*Assumptions!$C$17)+Assumptions!$C$53*Assumptions!$C$46*Assumptions!$C$51*(Assumptions!$C$13*Assumptions!$C$17)))*12>60,"Beyond 5 years",Assumptions!$C$34*(1+Assumptions!$C$35+Assumptions!$C$36+Assumptions!$C$37+Assumptions!$C$38+Assumptions!$C$39)/((Assumptions!$C$53*Assumptions!$C$46*(Assumptions!$C$13*Assumptions!$C$17)+Assumptions!$C$22/Assumptions!$C$20*Assumptions!$C$9+Assumptions!$C$22*Assumptions!$C$27+Assumptions!$C$23+Assumptions!$C$26)-(Assumptions!$C$40+Assumptions!$C$41+D18*Assumptions!$C$46*Assumptions!$C$8+Assumptions!$C$34*Assumptions!$C$10+Assumptions!$C$50*Assumptions!$C$46*(Assumptions!$C$13*Assumptions!$C$17)+Assumptions!$C$53*Assumptions!$C$46*Assumptions!$C$51*(Assumptions!$C$13*Assumptions!$C$17)))*12)) -> 35.087593 | E19: Electricity price remains at EIA base value
A22: Sentinel Prime AI — monitored coverage hours per day
A23: Output | B23: Low coverage | C23: Mid | D23: Base | E23: Interpretation
A24: Coverage hours/day | B24: 8 | C24: 16 | D24: 24 | E24: Avoided human-security coverage
A25: Simple payback | B25: =IF((B24*Assumptions!$C$65*(Assumptions!$C$13*Assumptions!$C$17)-(Assumptions!$C$63+Assumptions!$C$64*Assumptions!$C$65*Assumptions!$C$8+Assumptions!$C$57*Assumptions!$C$10+B24*Assumptions!$C$65*(Assumptions!$C$66+Assumptions!$C$67)*(Assumptions!$C$13*Assumptions!$C$17)))<=0,"Beyond 5 years",IF(Assumptions!$C$57*(1+Assumptions!$C$58+Assumptions!$C$59+Assumptions!$C$60+Assumptions!$C$61+Assumptions!$C$62)/(B24*Assumptions!$C$65*(Assumptions!$C$13*Assumptions!$C$17)-(Assumptions!$C$63+Assumptions!$C$64*Assumptions!$C$65*Assumptions!$C$8+Assumptions!$C$57*Assumptions!$C$10+B24*Assumptions!$C$65*(Assumptions!$C$66+Assumptions!$C$67)*(Assumptions!$C$13*Assumptions!$C$17)))*12>60,"Beyond 5 years",Assumptions!$C$57*(1+Assumptions!$C$58+Assumptions!$C$59+Assumptions!$C$60+Assumptions!$C$61+Assumptions!$C$62)/(B24*Assumptions!$C$65*(Assumptions!$C$13*Assumptions!$C$17)-(Assumptions!$C$63+Assumptions!$C$64*Assumptions!$C$65*Assumptions!$C$8+Assumptions!$C$57*Assumptions!$C$10+B24*Assumptions!$C$65*(Assumptions!$C$66+Assumptions!$C$67)*(Assumptions!$C$13*Assumptions!$C$17)))*12)) -> 28.791455 | C25: =IF((C24*Assumptions!$C$65*(Assumptions!$C$13*Assumptions!$C$17)-(Assumptions!$C$63+Assumptions!$C$64*Assumptions!$C$65*Assumptions!$C$8+Assumptions!$C$57*Assumptions!$C$10+C24*Assumptions!$C$65*(Assumptions!$C$66+Assumptions!$C$67)*(Assumptions!$C$13*Assumptions!$C$17)))<=0,"Beyond 5 years",IF(Assumptions!$C$57*(1+Assumptions!$C$58+Assumptions!$C$59+Assumptions!$C$60+Assumptions!$C$61+Assumptions!$C$62)/(C24*Assumptions!$C$65*(Assumptions!$C$13*Assumptions!$C$17)-(Assumptions!$C$63+Assumptions!$C$64*Assumptions!$C$65*Assumptions!$C$8+Assumptions!$C$57*Assumptions!$C$10+C24*Assumptions!$C$65*(Assumptions!$C$66+Assumptions!$C$67)*(Assumptions!$C$13*Assumptions!$C$17)))*12>60,"Beyond 5 years",Assumptions!$C$57*(1+Assumptions!$C$58+Assumptions!$C$59+Assumptions!$C$60+Assumptions!$C$61+Assumptions!$C$62)/(C24*Assumptions!$C$65*(Assumptions!$C$13*Assumptions!$C$17)-(Assumptions!$C$63+Assumptions!$C$64*Assumptions!$C$65*Assumptions!$C$8+Assumptions!$C$57*Assumptions!$C$10+C24*Assumptions!$C$65*(Assumptions!$C$66+Assumptions!$C$67)*(Assumptions!$C$13*Assumptions!$C$17)))*12)) -> 12.068637 | D25: =IF((D24*Assumptions!$C$65*(Assumptions!$C$13*Assumptions!$C$17)-(Assumptions!$C$63+Assumptions!$C$64*Assumptions!$C$65*Assumptions!$C$8+Assumptions!$C$57*Assumptions!$C$10+D24*Assumptions!$C$65*(Assumptions!$C$66+Assumptions!$C$67)*(Assumptions!$C$13*Assumptions!$C$17)))<=0,"Beyond 5 years",IF(Assumptions!$C$57*(1+Assumptions!$C$58+Assumptions!$C$59+Assumptions!$C$60+Assumptions!$C$61+Assumptions!$C$62)/(D24*Assumptions!$C$65*(Assumptions!$C$13*Assumptions!$C$17)-(Assumptions!$C$63+Assumptions!$C$64*Assumptions!$C$65*Assumptions!$C$8+Assumptions!$C$57*Assumptions!$C$10+D24*Assumptions!$C$65*(Assumptions!$C$66+Assumptions!$C$67)*(Assumptions!$C$13*Assumptions!$C$17)))*12>60,"Beyond 5 years",Assumptions!$C$57*(1+Assumptions!$C$58+Assumptions!$C$59+Assumptions!$C$60+Assumptions!$C$61+Assumptions!$C$62)/(D24*Assumptions!$C$65*(Assumptions!$C$13*Assumptions!$C$17)-(Assumptions!$C$63+Assumptions!$C$64*Assumptions!$C$65*Assumptions!$C$8+Assumptions!$C$57*Assumptions!$C$10+D24*Assumptions!$C$65*(Assumptions!$C$66+Assumptions!$C$67)*(Assumptions!$C$13*Assumptions!$C$17)))*12)) -> 7.634388 | E25: Includes 25% human oversight plus 2% downtime backup
A28: Both models — security-guard hourly wage
A29: Output | B29: Low | C29: Base | D29: High | E29: Interpretation
A30: Hourly wage | B30: 18.28 | C30: 20.42 | D30: 28.29 | E30: BLS median / mean / 90th percentile; each uses the same ECEC benefit factor
A31: Rover simple payback | B31: =IF(((Assumptions!$C$53*Assumptions!$C$46*(B30*Assumptions!$C$17)+Assumptions!$C$22/Assumptions!$C$20*Assumptions!$C$9+Assumptions!$C$22*Assumptions!$C$27+Assumptions!$C$23+Assumptions!$C$26)-(Assumptions!$C$40+Assumptions!$C$41+Assumptions!$C$45*Assumptions!$C$46*Assumptions!$C$8+Assumptions!$C$34*Assumptions!$C$10+Assumptions!$C$50*Assumptions!$C$46*(B30*Assumptions!$C$17)+Assumptions!$C$53*Assumptions!$C$46*Assumptions!$C$51*(B30*Assumptions!$C$17)))<=0,"Beyond 5 years",IF(Assumptions!$C$34*(1+Assumptions!$C$35+Assumptions!$C$36+Assumptions!$C$37+Assumptions!$C$38+Assumptions!$C$39)/((Assumptions!$C$53*Assumptions!$C$46*(B30*Assumptions!$C$17)+Assumptions!$C$22/Assumptions!$C$20*Assumptions!$C$9+Assumptions!$C$22*Assumptions!$C$27+Assumptions!$C$23+Assumptions!$C$26)-(Assumptions!$C$40+Assumptions!$C$41+Assumptions!$C$45*Assumptions!$C$46*Assumptions!$C$8+Assumptions!$C$34*Assumptions!$C$10+Assumptions!$C$50*Assumptions!$C$46*(B30*Assumptions!$C$17)+Assumptions!$C$53*Assumptions!$C$46*Assumptions!$C$51*(B30*Assumptions!$C$17)))*12>60,"Beyond 5 years",Assumptions!$C$34*(1+Assumptions!$C$35+Assumptions!$C$36+Assumptions!$C$37+Assumptions!$C$38+Assumptions!$C$39)/((Assumptions!$C$53*Assumptions!$C$46*(B30*Assumptions!$C$17)+Assumptions!$C$22/Assumptions!$C$20*Assumptions!$C$9+Assumptions!$C$22*Assumptions!$C$27+Assumptions!$C$23+Assumptions!$C$26)-(Assumptions!$C$40+Assumptions!$C$41+Assumptions!$C$45*Assumptions!$C$46*Assumptions!$C$8+Assumptions!$C$34*Assumptions!$C$10+Assumptions!$C$50*Assumptions!$C$46*(B30*Assumptions!$C$17)+Assumptions!$C$53*Assumptions!$C$46*Assumptions!$C$51*(B30*Assumptions!$C$17)))*12)) -> 40.131737 | C31: =IF(((Assumptions!$C$53*Assumptions!$C$46*(C30*Assumptions!$C$17)+Assumptions!$C$22/Assumptions!$C$20*Assumptions!$C$9+Assumptions!$C$22*Assumptions!$C$27+Assumptions!$C$23+Assumptions!$C$26)-(Assumptions!$C$40+Assumptions!$C$41+Assumptions!$C$45*Assumptions!$C$46*Assumptions!$C$8+Assumptions!$C$34*Assumptions!$C$10+Assumptions!$C$50*Assumptions!$C$46*(C30*Assumptions!$C$17)+Assumptions!$C$53*Assumptions!$C$46*Assumptions!$C$51*(C30*Assumptions!$C$17)))<=0,"Beyond 5 years",IF(Assumptions!$C$34*(1+Assumptions!$C$35+Assumptions!$C$36+Assumptions!$C$37+Assumptions!$C$38+Assumptions!$C$39)/((Assumptions!$C$53*Assumptions!$C$46*(C30*Assumptions!$C$17)+Assumptions!$C$22/Assumptions!$C$20*Assumptions!$C$9+Assumptions!$C$22*Assumptions!$C$27+Assumptions!$C$23+Assumptions!$C$26)-(Assumptions!$C$40+Assumptions!$C$41+Assumptions!$C$45*Assumptions!$C$46*Assumptions!$C$8+Assumptions!$C$34*Assumptions!$C$10+Assumptions!$C$50*Assumptions!$C$46*(C30*Assumptions!$C$17)+Assumptions!$C$53*Assumptions!$C$46*Assumptions!$C$51*(C30*Assumptions!$C$17)))*12>60,"Beyond 5 years",Assumptions!$C$34*(1+Assumptions!$C$35+Assumptions!$C$36+Assumptions!$C$37+Assumptions!$C$38+Assumptions!$C$39)/((Assumptions!$C$53*Assumptions!$C$46*(C30*Assumptions!$C$17)+Assumptions!$C$22/Assumptions!$C$20*Assumptions!$C$9+Assumptions!$C$22*Assumptions!$C$27+Assumptions!$C$23+Assumptions!$C$26)-(Assumptions!$C$40+Assumptions!$C$41+Assumptions!$C$45*Assumptions!$C$46*Assumptions!$C$8+Assumptions!$C$34*Assumptions!$C$10+Assumptions!$C$50*Assumptions!$C$46*(C30*Assumptions!$C$17)+Assumptions!$C$53*Assumptions!$C$46*Assumptions!$C$51*(C30*Assumptions!$C$17)))*12)) -> 35.055225 | D31: =IF(((Assumptions!$C$53*Assumptions!$C$46*(D30*Assumptions!$C$17)+Assumptions!$C$22/Assumptions!$C$20*Assumptions!$C$9+Assumptions!$C$22*Assumptions!$C$27+Assumptions!$C$23+Assumptions!$C$26)-(Assumptions!$C$40+Assumptions!$C$41+Assumptions!$C$45*Assumptions!$C$46*Assumptions!$C$8+Assumptions!$C$34*Assumptions!$C$10+Assumptions!$C$50*Assumptions!$C$46*(D30*Assumptions!$C$17)+Assumptions!$C$53*Assumptions!$C$46*Assumptions!$C$51*(D30*Assumptions!$C$17)))<=0,"Beyond 5 years",IF(Assumptions!$C$34*(1+Assumptions!$C$35+Assumptions!$C$36+Assumptions!$C$37+Assumptions!$C$38+Assumptions!$C$39)/((Assumptions!$C$53*Assumptions!$C$46*(D30*Assumptions!$C$17)+Assumptions!$C$22/Assumptions!$C$20*Assumptions!$C$9+Assumptions!$C$22*Assumptions!$C$27+Assumptions!$C$23+Assumptions!$C$26)-(Assumptions!$C$40+Assumptions!$C$41+Assumptions!$C$45*Assumptions!$C$46*Assumptions!$C$8+Assumptions!$C$34*Assumptions!$C$10+Assumptions!$C$50*Assumptions!$C$46*(D30*Assumptions!$C$17)+Assumptions!$C$53*Assumptions!$C$46*Assumptions!$C$51*(D30*Assumptions!$C$17)))*12>60,"Beyond 5 years",Assumptions!$C$34*(1+Assumptions!$C$35+Assumptions!$C$36+Assumptions!$C$37+Assumptions!$C$38+Assumptions!$C$39)/((Assumptions!$C$53*Assumptions!$C$46*(D30*Assumptions!$C$17)+Assumptions!$C$22/Assumptions!$C$20*Assumptions!$C$9+Assumptions!$C$22*Assumptions!$C$27+Assumptions!$C$23+Assumptions!$C$26)-(Assumptions!$C$40+Assumptions!$C$41+Assumptions!$C$45*Assumptions!$C$46*Assumptions!$C$8+Assumptions!$C$34*Assumptions!$C$10+Assumptions!$C$50*Assumptions!$C$46*(D30*Assumptions!$C$17)+Assumptions!$C$53*Assumptions!$C$46*Assumptions!$C$51*(D30*Assumptions!$C$17)))*12)) -> 23.925237 | E31: Coverage remains at 8 hours/day
A32: Sentinel simple payback | B32: =IF((Assumptions!$C$69*Assumptions!$C$65*(B30*Assumptions!$C$17)-(Assumptions!$C$63+Assumptions!$C$64*Assumptions!$C$65*Assumptions!$C$8+Assumptions!$C$57*Assumptions!$C$10+Assumptions!$C$69*Assumptions!$C$65*(Assumptions!$C$66+Assumptions!$C$67)*(B30*Assumptions!$C$17)))<=0,"Beyond 5 years",IF(Assumptions!$C$57*(1+Assumptions!$C$58+Assumptions!$C$59+Assumptions!$C$60+Assumptions!$C$61+Assumptions!$C$62)/(Assumptions!$C$69*Assumptions!$C$65*(B30*Assumptions!$C$17)-(Assumptions!$C$63+Assumptions!$C$64*Assumptions!$C$65*Assumptions!$C$8+Assumptions!$C$57*Assumptions!$C$10+Assumptions!$C$69*Assumptions!$C$65*(Assumptions!$C$66+Assumptions!$C$67)*(B30*Assumptions!$C$17)))*12>60,"Beyond 5 years",Assumptions!$C$57*(1+Assumptions!$C$58+Assumptions!$C$59+Assumptions!$C$60+Assumptions!$C$61+Assumptions!$C$62)/(Assumptions!$C$69*Assumptions!$C$65*(B30*Assumptions!$C$17)-(Assumptions!$C$63+Assumptions!$C$64*Assumptions!$C$65*Assumptions!$C$8+Assumptions!$C$57*Assumptions!$C$10+Assumptions!$C$69*Assumptions!$C$65*(Assumptions!$C$66+Assumptions!$C$67)*(B30*Assumptions!$C$17)))*12)) -> 8.6314571 | C32: =IF((Assumptions!$C$69*Assumptions!$C$65*(C30*Assumptions!$C$17)-(Assumptions!$C$63+Assumptions!$C$64*Assumptions!$C$65*Assumptions!$C$8+Assumptions!$C$57*Assumptions!$C$10+Assumptions!$C$69*Assumptions!$C$65*(Assumptions!$C$66+Assumptions!$C$67)*(C30*Assumptions!$C$17)))<=0,"Beyond 5 years",IF(Assumptions!$C$57*(1+Assumptions!$C$58+Assumptions!$C$59+Assumptions!$C$60+Assumptions!$C$61+Assumptions!$C$62)/(Assumptions!$C$69*Assumptions!$C$65*(C30*Assumptions!$C$17)-(Assumptions!$C$63+Assumptions!$C$64*Assumptions!$C$65*Assumptions!$C$8+Assumptions!$C$57*Assumptions!$C$10+Assumptions!$C$69*Assumptions!$C$65*(Assumptions!$C$66+Assumptions!$C$67)*(C30*Assumptions!$C$17)))*12>60,"Beyond 5 years",Assumptions!$C$57*(1+Assumptions!$C$58+Assumptions!$C$59+Assumptions!$C$60+Assumptions!$C$61+Assumptions!$C$62)/(Assumptions!$C$69*Assumptions!$C$65*(C30*Assumptions!$C$17)-(Assumptions!$C$63+Assumptions!$C$64*Assumptions!$C$65*Assumptions!$C$8+Assumptions!$C$57*Assumptions!$C$10+Assumptions!$C$69*Assumptions!$C$65*(Assumptions!$C$66+Assumptions!$C$67)*(C30*Assumptions!$C$17)))*12)) -> 7.634388 | D32: =IF((Assumptions!$C$69*Assumptions!$C$65*(D30*Assumptions!$C$17)-(Assumptions!$C$63+Assumptions!$C$64*Assumptions!$C$65*Assumptions!$C$8+Assumptions!$C$57*Assumptions!$C$10+Assumptions!$C$69*Assumptions!$C$65*(Assumptions!$C$66+Assumptions!$C$67)*(D30*Assumptions!$C$17)))<=0,"Beyond 5 years",IF(Assumptions!$C$57*(1+Assumptions!$C$58+Assumptions!$C$59+Assumptions!$C$60+Assumptions!$C$61+Assumptions!$C$62)/(Assumptions!$C$69*Assumptions!$C$65*(D30*Assumptions!$C$17)-(Assumptions!$C$63+Assumptions!$C$64*Assumptions!$C$65*Assumptions!$C$8+Assumptions!$C$57*Assumptions!$C$10+Assumptions!$C$69*Assumptions!$C$65*(Assumptions!$C$66+Assumptions!$C$67)*(D30*Assumptions!$C$17)))*12>60,"Beyond 5 years",Assumptions!$C$57*(1+Assumptions!$C$58+Assumptions!$C$59+Assumptions!$C$60+Assumptions!$C$61+Assumptions!$C$62)/(Assumptions!$C$69*Assumptions!$C$65*(D30*Assumptions!$C$17)-(Assumptions!$C$63+Assumptions!$C$64*Assumptions!$C$65*Assumptions!$C$8+Assumptions!$C$57*Assumptions!$C$10+Assumptions!$C$69*Assumptions!$C$65*(Assumptions!$C$66+Assumptions!$C$67)*(D30*Assumptions!$C$17)))*12)) -> 5.3581526 | E32: Coverage remains at 24 hours/day
A35: Main result
A36: Largest break-even driver | B36: Avoided coverage hours | E36: Labor is the largest recurring cost in both alternatives.
A37: Public data needed | B37: Local/industry wage and public security contracts | E37: Use BLS metro/industry wages and public bid documents with required staffing hours.

Sheet Checks
A1: W03 Five-Year TCO Analysis — Checks
A5: Check | B5: Actual | C5: Expected | D5: Difference | E5: Tolerance | F5: Status | G5: Notes
A6: Rover five-year total ties to schedule | B6: ='Aido Rover'!B43 -> 346631.92 | C6: =SUM('Aido Rover'!B20:F20) -> 346631.92 | D6: =B6-C6 -> 0 | E6: 0.01 | F6: =IF(ABS(D6)<=E6,"PASS","FAIL") -> PASS | G6: Expected value is the sum of annual Rover totals.
A7: Human patrol five-year total ties to schedule | B7: ='Aido Rover'!B44 -> 450137.02 | C7: =SUM('Aido Rover'!B28:F28) -> 450137.02 | D7: =B7-C7 -> 0 | E7: 0.01 | F7: =IF(ABS(D7)<=E7,"PASS","FAIL") -> PASS | G7: Expected value is the sum of annual human-patrol totals.
A8: Rover battery replacement count | B8: =COUNTIF('Aido Rover'!B16:F16,">0") -> 2 | C8: 2 | D8: =B8-C8 -> 0 | E8: 0 | F8: =IF(ABS(D8)<=E8,"PASS","FAIL") -> PASS | G8: 1.6 cycles/day crosses the 1,000-cycle life in Years 2 and 4.
A9: Rover daily electricity is capacity-based | B9: =Assumptions!C45 -> 4 | C9: =Assumptions!C42*Assumptions!C43/Assumptions!C44 -> 4 | D9: =B9-C9 -> 0 | E9: 0.01 | F9: =IF(ABS(D9)<=E9,"PASS","FAIL") -> PASS | G9: Daily grid energy must equal battery capacity × cycles ÷ charging efficiency.
A10: Shared route converts from miles to kilometers | B10: =Assumptions!C22*Assumptions!C19 -> 7300 | C10: =Assumptions!C48 -> 7300 | D10: =B10-C10 -> 0 | E10: 0.01 | F10: =IF(ABS(D10)<=E10,"PASS","FAIL") -> PASS | G10: Vehicle miles convert back to the same annual route used by Rover.
A11: Rover residual value occurs once | B11: =COUNTIF('Aido Rover'!B19:F19,"<0") -> 1 | C11: 1 | D11: =B11-C11 -> 0 | E11: 0 | F11: =IF(ABS(D11)<=E11,"PASS","FAIL") -> PASS | G11: Residual value is recognized only in Year 5.
A12: Sentinel five-year total ties to schedule | B12: ='Sentinel Prime AI'!B36 -> 509446.89 | C12: =SUM('Sentinel Prime AI'!B19:F19) -> 509446.89 | D12: =B12-C12 -> 0 | E12: 0.01 | F12: =IF(ABS(D12)<=E12,"PASS","FAIL") -> PASS | G12: Expected value is the sum of annual Sentinel totals.
A13: Sentinel 24/7 power is positive each year | B13: =COUNTIF('Sentinel Prime AI'!B13:F13,">0") -> 5 | C13: 5 | D13: =B13-C13 -> 0 | E13: 0 | F13: =IF(ABS(D13)<=E13,"PASS","FAIL") -> PASS | G13: Electricity cost appears in all five years.
A16: MODEL STATUS | F16: =IF(COUNTIF(F6:F13,"FAIL")=0,"PASS","FAIL") -> PASS

Sheet Sources
A1: W03 Five-Year TCO Analysis — Sources
A5: Source ID | B5: Model Input / Use | C5: Value / Unit | D5: Period | E5: Source | F5: URL | G5: Notes
A6: S01 | B6: Security-guard wage | C6: $18.28 median; $20.42 mean; $28.29 P90 | D6: May 2025 | E6: BLS OEWS National | F6: https://www.bls.gov/oes/tables.htm | G6: OCC_CODE 33-9032. Mean is the base case; median and P90 are sensitivity cases.
A7: S02 | B7: Benefit load | C7: $23.63 total compensation / $18.15 wages | D7: March 2026 | E7: BLS Employer Costs for Employee Compensation | F7: https://www.bls.gov/news.release/pdf/ecec.pdf | G7: Table 4, service occupations; factor = 1.302.
